2019-07-22 13:58:15,472 ERROR: Exception on /menu/armadopika [POST] [in C:\Users\User\AppData\Local\Programs\Python\Python37\lib\site-packages\flask\app.py:1891]
Traceback (most recent call last):
  File "C:\Users\User\AppData\Local\Programs\Python\Python37\lib\site-packages\sqlalchemy\engine\base.py", line 1244, in _execute_context
    cursor, statement, parameters, context
  File "C:\Users\User\AppData\Local\Programs\Python\Python37\lib\site-packages\sqlalchemy\engine\default.py", line 550, in do_execute
    cursor.execute(statement, parameters)
sqlite3.OperationalError: database is locked

The above exception was the direct cause of the following exception:

Traceback (most recent call last):
  File "C:\Users\User\AppData\Local\Programs\Python\Python37\lib\site-packages\flask\app.py", line 2446, in wsgi_app
    response = self.full_dispatch_request()
  File "C:\Users\User\AppData\Local\Programs\Python\Python37\lib\site-packages\flask\app.py", line 1951, in full_dispatch_request
    rv = self.handle_user_exception(e)
  File "C:\Users\User\AppData\Local\Programs\Python\Python37\lib\site-packages\flask\app.py", line 1820, in handle_user_exception
    reraise(exc_type, exc_value, tb)
  File "C:\Users\User\AppData\Local\Programs\Python\Python37\lib\site-packages\flask\_compat.py", line 39, in reraise
    raise value
  File "C:\Users\User\AppData\Local\Programs\Python\Python37\lib\site-packages\flask\app.py", line 1949, in full_dispatch_request
    rv = self.dispatch_request()
  File "C:\Users\User\AppData\Local\Programs\Python\Python37\lib\site-packages\flask\app.py", line 1935, in dispatch_request
    return self.view_functions[rule.endpoint](**req.view_args)
  File "C:\Users\User\AppData\Local\Programs\Python\Python37\lib\site-packages\flask_login\utils.py", line 261, in decorated_view
    return func(*args, **kwargs)
  File "C:\Users\User\Desktop\pyflaskapp\flask1\routes.py", line 96, in menu_armadopika
    stockinsu = db.query(StockInsumo).get(pikainsu.insumo_id)
  File "C:\Users\User\AppData\Local\Programs\Python\Python37\lib\site-packages\sqlalchemy\orm\query.py", line 959, in get
    return self._get_impl(ident, loading.load_on_pk_identity)
  File "C:\Users\User\AppData\Local\Programs\Python\Python37\lib\site-packages\sqlalchemy\orm\query.py", line 1069, in _get_impl
    return db_load_fn(self, primary_key_identity)
  File "C:\Users\User\AppData\Local\Programs\Python\Python37\lib\site-packages\sqlalchemy\orm\loading.py", line 282, in load_on_pk_identity
    return q.one()
  File "C:\Users\User\AppData\Local\Programs\Python\Python37\lib\site-packages\sqlalchemy\orm\query.py", line 3282, in one
    ret = self.one_or_none()
  File "C:\Users\User\AppData\Local\Programs\Python\Python37\lib\site-packages\sqlalchemy\orm\query.py", line 3251, in one_or_none
    ret = list(self)
  File "C:\Users\User\AppData\Local\Programs\Python\Python37\lib\site-packages\sqlalchemy\orm\query.py", line 3323, in __iter__
    self.session._autoflush()
  File "C:\Users\User\AppData\Local\Programs\Python\Python37\lib\site-packages\sqlalchemy\orm\session.py", line 1588, in _autoflush
    util.raise_from_cause(e)
  File "C:\Users\User\AppData\Local\Programs\Python\Python37\lib\site-packages\sqlalchemy\util\compat.py", line 399, in raise_from_cause
    reraise(type(exception), exception, tb=exc_tb, cause=cause)
  File "C:\Users\User\AppData\Local\Programs\Python\Python37\lib\site-packages\sqlalchemy\util\compat.py", line 154, in reraise
    raise value
  File "C:\Users\User\AppData\Local\Programs\Python\Python37\lib\site-packages\sqlalchemy\orm\session.py", line 1577, in _autoflush
    self.flush()
  File "C:\Users\User\AppData\Local\Programs\Python\Python37\lib\site-packages\sqlalchemy\orm\session.py", line 2459, in flush
    self._flush(objects)
  File "C:\Users\User\AppData\Local\Programs\Python\Python37\lib\site-packages\sqlalchemy\orm\session.py", line 2597, in _flush
    transaction.rollback(_capture_exception=True)
  File "C:\Users\User\AppData\Local\Programs\Python\Python37\lib\site-packages\sqlalchemy\util\langhelpers.py", line 68, in __exit__
    compat.reraise(exc_type, exc_value, exc_tb)
  File "C:\Users\User\AppData\Local\Programs\Python\Python37\lib\site-packages\sqlalchemy\util\compat.py", line 154, in reraise
    raise value
  File "C:\Users\User\AppData\Local\Programs\Python\Python37\lib\site-packages\sqlalchemy\orm\session.py", line 2557, in _flush
    flush_context.execute()
  File "C:\Users\User\AppData\Local\Programs\Python\Python37\lib\site-packages\sqlalchemy\orm\unitofwork.py", line 422, in execute
    rec.execute(self)
  File "C:\Users\User\AppData\Local\Programs\Python\Python37\lib\site-packages\sqlalchemy\orm\unitofwork.py", line 589, in execute
    uow,
  File "C:\Users\User\AppData\Local\Programs\Python\Python37\lib\site-packages\sqlalchemy\orm\persistence.py", line 236, in save_obj
    update,
  File "C:\Users\User\AppData\Local\Programs\Python\Python37\lib\site-packages\sqlalchemy\orm\persistence.py", line 996, in _emit_update_statements
    statement, multiparams
  File "C:\Users\User\AppData\Local\Programs\Python\Python37\lib\site-packages\sqlalchemy\engine\base.py", line 988, in execute
    return meth(self, multiparams, params)
  File "C:\Users\User\AppData\Local\Programs\Python\Python37\lib\site-packages\sqlalchemy\sql\elements.py", line 287, in _execute_on_connection
    return connection._execute_clauseelement(self, multiparams, params)
  File "C:\Users\User\AppData\Local\Programs\Python\Python37\lib\site-packages\sqlalchemy\engine\base.py", line 1107, in _execute_clauseelement
    distilled_params,
  File "C:\Users\User\AppData\Local\Programs\Python\Python37\lib\site-packages\sqlalchemy\engine\base.py", line 1248, in _execute_context
    e, statement, parameters, cursor, context
  File "C:\Users\User\AppData\Local\Programs\Python\Python37\lib\site-packages\sqlalchemy\engine\base.py", line 1466, in _handle_dbapi_exception
    util.raise_from_cause(sqlalchemy_exception, exc_info)
  File "C:\Users\User\AppData\Local\Programs\Python\Python37\lib\site-packages\sqlalchemy\util\compat.py", line 399, in raise_from_cause
    reraise(type(exception), exception, tb=exc_tb, cause=cause)
  File "C:\Users\User\AppData\Local\Programs\Python\Python37\lib\site-packages\sqlalchemy\util\compat.py", line 153, in reraise
    raise value.with_traceback(tb)
  File "C:\Users\User\AppData\Local\Programs\Python\Python37\lib\site-packages\sqlalchemy\engine\base.py", line 1244, in _execute_context
    cursor, statement, parameters, context
  File "C:\Users\User\AppData\Local\Programs\Python\Python37\lib\site-packages\sqlalchemy\engine\default.py", line 550, in do_execute
    cursor.execute(statement, parameters)
sqlalchemy.exc.OperationalError: (raised as a result of Query-invoked autoflush; consider using a session.no_autoflush block if this flush is occurring prematurely)
(sqlite3.OperationalError) database is locked
[SQL: UPDATE stockinsumo SET cantidad=?, fecha=? WHERE stockinsumo.insumo_id = ?]
[parameters: (0, '2019-07-22 13:58:10.403981', 1)]
(Background on this error at: http://sqlalche.me/e/e3q8)
2019-07-22 20:17:31,379 ERROR: Exception on /menu/agregelimgcode [POST] [in C:\Users\User\AppData\Local\Programs\Python\Python37\lib\site-packages\flask\app.py:1891]
Traceback (most recent call last):
  File "C:\Users\User\AppData\Local\Programs\Python\Python37\lib\site-packages\flask\app.py", line 2446, in wsgi_app
    response = self.full_dispatch_request()
  File "C:\Users\User\AppData\Local\Programs\Python\Python37\lib\site-packages\flask\app.py", line 1951, in full_dispatch_request
    rv = self.handle_user_exception(e)
  File "C:\Users\User\AppData\Local\Programs\Python\Python37\lib\site-packages\flask\app.py", line 1820, in handle_user_exception
    reraise(exc_type, exc_value, tb)
  File "C:\Users\User\AppData\Local\Programs\Python\Python37\lib\site-packages\flask\_compat.py", line 39, in reraise
    raise value
  File "C:\Users\User\AppData\Local\Programs\Python\Python37\lib\site-packages\flask\app.py", line 1949, in full_dispatch_request
    rv = self.dispatch_request()
  File "C:\Users\User\AppData\Local\Programs\Python\Python37\lib\site-packages\flask\app.py", line 1935, in dispatch_request
    return self.view_functions[rule.endpoint](**req.view_args)
  File "C:\Users\User\AppData\Local\Programs\Python\Python37\lib\site-packages\flask_login\utils.py", line 261, in decorated_view
    return func(*args, **kwargs)
  File "C:\Users\User\Desktop\pyflaskapp\flask1\routes.py", line 991, in menu_agregelimgcode
    db.query(Gcode).filter(Gcode.id==gcod.id).delete()
AttributeError: 'NoneType' object has no attribute 'id'
