2019-07-22 13:51:34,679 ERROR: Exception on /menu/rolloplaabierto [POST] [in C:\Users\User\AppData\Local\Programs\Python\Python37\lib\site-packages\flask\app.py:1891]
Traceback (most recent call last):
  File "C:\Users\User\AppData\Local\Programs\Python\Python37\lib\site-packages\flask\app.py", line 2446, in wsgi_app
    response = self.full_dispatch_request()
  File "C:\Users\User\AppData\Local\Programs\Python\Python37\lib\site-packages\flask\app.py", line 1951, in full_dispatch_request
    rv = self.handle_user_exception(e)
  File "C:\Users\User\AppData\Local\Programs\Python\Python37\lib\site-packages\flask\app.py", line 1820, in handle_user_exception
    reraise(exc_type, exc_value, tb)
  File "C:\Users\User\AppData\Local\Programs\Python\Python37\lib\site-packages\flask\_compat.py", line 39, in reraise
    raise value
  File "C:\Users\User\AppData\Local\Programs\Python\Python37\lib\site-packages\flask\app.py", line 1949, in full_dispatch_request
    rv = self.dispatch_request()
  File "C:\Users\User\AppData\Local\Programs\Python\Python37\lib\site-packages\flask\app.py", line 1935, in dispatch_request
    return self.view_functions[rule.endpoint](**req.view_args)
  File "C:\Users\User\AppData\Local\Programs\Python\Python37\lib\site-packages\flask_login\utils.py", line 261, in decorated_view
    return func(*args, **kwargs)
  File "C:\Users\User\Desktop\pyflaskapp\flask1\routes.py", line 406, in menu_rolloplaabierto
    check_alarmas()
  File "C:\Users\User\Desktop\pyflaskapp\flask1\alarmas.py", line 43, in check_alarmas
    mando_mail = check_insumo_stock(alarma, stock)
  File "C:\Users\User\Desktop\pyflaskapp\flask1\alarmas.py", line 51, in check_insumo_stock
    mandar_alarma(alarma.insumo.nombre, stock.cantidad, alarma.cantidad)
  File "C:\Users\User\Desktop\pyflaskapp\flask1\alarmas.py", line 67, in mandar_alarma
    s.sendmail("stockcogonauts@gmail.com", "info@cogonauts.com", message)
  File "C:\Users\User\AppData\Local\Programs\Python\Python37\lib\smtplib.py", line 855, in sendmail
    msg = _fix_eols(msg).encode('ascii')
UnicodeEncodeError: 'ascii' codec can't encode character '\xe1' in position 36: ordinal not in range(128)
2019-07-22 13:51:34,934 ERROR: Exception on /menu/rolloplaabierto [POST] [in C:\Users\User\AppData\Local\Programs\Python\Python37\lib\site-packages\flask\app.py:1891]
Traceback (most recent call last):
  File "C:\Users\User\AppData\Local\Programs\Python\Python37\lib\site-packages\flask\app.py", line 2446, in wsgi_app
    response = self.full_dispatch_request()
  File "C:\Users\User\AppData\Local\Programs\Python\Python37\lib\site-packages\flask\app.py", line 1951, in full_dispatch_request
    rv = self.handle_user_exception(e)
  File "C:\Users\User\AppData\Local\Programs\Python\Python37\lib\site-packages\flask\app.py", line 1820, in handle_user_exception
    reraise(exc_type, exc_value, tb)
  File "C:\Users\User\AppData\Local\Programs\Python\Python37\lib\site-packages\flask\_compat.py", line 39, in reraise
    raise value
  File "C:\Users\User\AppData\Local\Programs\Python\Python37\lib\site-packages\flask\app.py", line 1949, in full_dispatch_request
    rv = self.dispatch_request()
  File "C:\Users\User\AppData\Local\Programs\Python\Python37\lib\site-packages\flask\app.py", line 1935, in dispatch_request
    return self.view_functions[rule.endpoint](**req.view_args)
  File "C:\Users\User\AppData\Local\Programs\Python\Python37\lib\site-packages\flask_login\utils.py", line 261, in decorated_view
    return func(*args, **kwargs)
  File "C:\Users\User\Desktop\pyflaskapp\flask1\routes.py", line 406, in menu_rolloplaabierto
    check_alarmas()
  File "C:\Users\User\Desktop\pyflaskapp\flask1\alarmas.py", line 43, in check_alarmas
    mando_mail = check_insumo_stock(alarma, stock)
  File "C:\Users\User\Desktop\pyflaskapp\flask1\alarmas.py", line 51, in check_insumo_stock
    mandar_alarma(alarma.insumo.nombre, stock.cantidad, alarma.cantidad)
  File "C:\Users\User\Desktop\pyflaskapp\flask1\alarmas.py", line 67, in mandar_alarma
    s.sendmail("stockcogonauts@gmail.com", "info@cogonauts.com", message)
  File "C:\Users\User\AppData\Local\Programs\Python\Python37\lib\smtplib.py", line 855, in sendmail
    msg = _fix_eols(msg).encode('ascii')
UnicodeEncodeError: 'ascii' codec can't encode character '\xe1' in position 36: ordinal not in range(128)
2019-07-22 13:51:35,072 ERROR: Exception on /menu/rolloplaabierto [POST] [in C:\Users\User\AppData\Local\Programs\Python\Python37\lib\site-packages\flask\app.py:1891]
Traceback (most recent call last):
  File "C:\Users\User\AppData\Local\Programs\Python\Python37\lib\site-packages\flask\app.py", line 2446, in wsgi_app
    response = self.full_dispatch_request()
  File "C:\Users\User\AppData\Local\Programs\Python\Python37\lib\site-packages\flask\app.py", line 1951, in full_dispatch_request
    rv = self.handle_user_exception(e)
  File "C:\Users\User\AppData\Local\Programs\Python\Python37\lib\site-packages\flask\app.py", line 1820, in handle_user_exception
    reraise(exc_type, exc_value, tb)
  File "C:\Users\User\AppData\Local\Programs\Python\Python37\lib\site-packages\flask\_compat.py", line 39, in reraise
    raise value
  File "C:\Users\User\AppData\Local\Programs\Python\Python37\lib\site-packages\flask\app.py", line 1949, in full_dispatch_request
    rv = self.dispatch_request()
  File "C:\Users\User\AppData\Local\Programs\Python\Python37\lib\site-packages\flask\app.py", line 1935, in dispatch_request
    return self.view_functions[rule.endpoint](**req.view_args)
  File "C:\Users\User\AppData\Local\Programs\Python\Python37\lib\site-packages\flask_login\utils.py", line 261, in decorated_view
    return func(*args, **kwargs)
  File "C:\Users\User\Desktop\pyflaskapp\flask1\routes.py", line 406, in menu_rolloplaabierto
    check_alarmas()
  File "C:\Users\User\Desktop\pyflaskapp\flask1\alarmas.py", line 43, in check_alarmas
    mando_mail = check_insumo_stock(alarma, stock)
  File "C:\Users\User\Desktop\pyflaskapp\flask1\alarmas.py", line 51, in check_insumo_stock
    mandar_alarma(alarma.insumo.nombre, stock.cantidad, alarma.cantidad)
  File "C:\Users\User\Desktop\pyflaskapp\flask1\alarmas.py", line 67, in mandar_alarma
    s.sendmail("stockcogonauts@gmail.com", "info@cogonauts.com", message)
  File "C:\Users\User\AppData\Local\Programs\Python\Python37\lib\smtplib.py", line 855, in sendmail
    msg = _fix_eols(msg).encode('ascii')
UnicodeEncodeError: 'ascii' codec can't encode character '\xe1' in position 36: ordinal not in range(128)
2019-07-22 13:55:13,848 ERROR: Exception on /menu/armadopika [POST] [in C:\Users\User\AppData\Local\Programs\Python\Python37\lib\site-packages\flask\app.py:1891]
Traceback (most recent call last):
  File "C:\Users\User\AppData\Local\Programs\Python\Python37\lib\site-packages\flask\app.py", line 2446, in wsgi_app
    response = self.full_dispatch_request()
  File "C:\Users\User\AppData\Local\Programs\Python\Python37\lib\site-packages\flask\app.py", line 1951, in full_dispatch_request
    rv = self.handle_user_exception(e)
  File "C:\Users\User\AppData\Local\Programs\Python\Python37\lib\site-packages\flask\app.py", line 1820, in handle_user_exception
    reraise(exc_type, exc_value, tb)
  File "C:\Users\User\AppData\Local\Programs\Python\Python37\lib\site-packages\flask\_compat.py", line 39, in reraise
    raise value
  File "C:\Users\User\AppData\Local\Programs\Python\Python37\lib\site-packages\flask\app.py", line 1949, in full_dispatch_request
    rv = self.dispatch_request()
  File "C:\Users\User\AppData\Local\Programs\Python\Python37\lib\site-packages\flask\app.py", line 1935, in dispatch_request
    return self.view_functions[rule.endpoint](**req.view_args)
  File "C:\Users\User\AppData\Local\Programs\Python\Python37\lib\site-packages\flask_login\utils.py", line 261, in decorated_view
    return func(*args, **kwargs)
  File "C:\Users\User\Desktop\pyflaskapp\flask1\routes.py", line 113, in menu_armadopika
    check_alarmas()
  File "C:\Users\User\Desktop\pyflaskapp\flask1\alarmas.py", line 43, in check_alarmas
    mando_mail = check_insumo_stock(alarma, stock)
  File "C:\Users\User\Desktop\pyflaskapp\flask1\alarmas.py", line 51, in check_insumo_stock
    mandar_alarma(alarma.insumo.nombre, stock.cantidad, alarma.cantidad)
  File "C:\Users\User\Desktop\pyflaskapp\flask1\alarmas.py", line 67, in mandar_alarma
    s.sendmail("stockcogonauts@gmail.com", "info@cogonauts.com", message)
  File "C:\Users\User\AppData\Local\Programs\Python\Python37\lib\smtplib.py", line 855, in sendmail
    msg = _fix_eols(msg).encode('ascii')
UnicodeEncodeError: 'ascii' codec can't encode character '\xe1' in position 36: ordinal not in range(128)
